Workbook
Name NativeTimeline_Sale_Date: #N/A
Name Slicer_Property_Type: #N/A
Name Slicer_Town: #N/A

Sheet Dashboard

Sheet KPI_Calculations
A1: Average of Sale_Price
A2: 500619.27
A8: Count of Sale_Price
A9: 4901
A16: Row Labels | B16: Average of Price Per Sq Ft
A17: Stamford | B17: 276.9192
A18: Norwalk | B18: 275.75741
A19: Hartford | B19: 269.80365
A20: Waterbury | B20: 266.13523
A21: Bridgeport | B21: 260.5532
A22: Danbury | B22: 259.09382
A23: New Haven | B23: 259.04309
A24: Grand Total | B24: 265.67952
A33: Row Labels | B33: Average of Sale_Price
A34: Norwalk | B34: 519384.57
A35: Stamford | B35: 508894.35
A36: Danbury | B36: 505984.57
A37: Waterbury | B37: 503075.79
A38: Hartford | B38: 501577.18
A39: Bridgeport | B39: 493043.44
A40: New Haven | B40: 490024.89
A41: Grand Total | B41: 500619.27
A49: Row Labels | B49: Count of Sale_Price
A50: New Haven | B50: 998
A51: Hartford | B51: 987
A52: Bridgeport | B52: 952
A53: Stamford | B53: 516
A54: Danbury | B54: 497
A55: Waterbury | B55: 487
A56: Norwalk | B56: 464
A57: Grand Total | B57: 4901

Sheet Raw_Data
A1: Sale_Date | B1: Month | C1: Year | D1: Address | E1: Town | F1: Property_Type | G1: Bedrooms | H1: Square_Feet | I1: Sale_Price | J1: Price Per Sq Ft
A2: 43780 | B2: =TEXT(Raw_Data!$A2, "MMM") -> Nov | C2: =YEAR(Raw_Data!$A2) -> 2019 | D2: 758 Maple Ave | E2: New Haven | F2: Condo | G2: 3 | H2: 1978 | I2: 521480 | J2: =Raw_Data!$I2/Raw_Data!$H2 -> 263.64004
A3: 39293 | B3: =TEXT(Raw_Data!$A3, "MMM") -> Jul | C3: =YEAR(Raw_Data!$A3) -> 2007 | D3: 294 Pine Rd | E3: Waterbury | F3: Condo | G3: 4 | H3: 1223 | I3: 705776 | J3: =Raw_Data!$I3/Raw_Data!$H3 -> 577.08585
A4: 43021 | B4: =TEXT(Raw_Data!$A4, "MMM") -> Oct | C4: =YEAR(Raw_Data!$A4) -> 2017 | D4: 579 Pine Rd | E4: New Haven | F4: Single Family | G4: 3 | H4: 2611 | I4: 226876 | J4: =Raw_Data!$I4/Raw_Data!$H4 -> 86.892378
A5: 40510 | B5: =TEXT(Raw_Data!$A5, "MMM") -> Nov | C5: =YEAR(Raw_Data!$A5) -> 2010 | D5: 799 Elm St | E5: Waterbury | F5: Apartment | G5: 4 | H5: 3316 | I5: 674883 | J5: =Raw_Data!$I5/Raw_Data!$H5 -> 203.52322
A6: 40017 | B6: =TEXT(Raw_Data!$A6, "MMM") -> Jul | C6: =YEAR(Raw_Data!$A6) -> 2009 | D6: 436 Maple Ave | E6: New Haven | F6: Single Family | G6: 4 | H6: 883 | I6: 355887 | J6: =Raw_Data!$I6/Raw_Data!$H6 -> 403.04304
A7: 41807 | B7: =TEXT(Raw_Data!$A7, "MMM") -> Jun | C7: =YEAR(Raw_Data!$A7) -> 2014 | D7: 103 Pine Rd | E7: Stamford | F7: Condo | G7: 3 | H7: 3305 | I7: 849855 | J7: =Raw_Data!$I7/Raw_Data!$H7 -> 257.14221
A8: 40268 | B8: =TEXT(Raw_Data!$A8, "MMM") -> Mar | C8: =YEAR(Raw_Data!$A8) -> 2010 | D8: 175 Elm St | E8: Norwalk | F8: Condo | G8: 3 | H8: 2376 | I8: 661446 | J8: =Raw_Data!$I8/Raw_Data!$H8 -> 278.38636
A9: 40085 | B9: =TEXT(Raw_Data!$A9, "MMM") -> Sep | C9: =YEAR(Raw_Data!$A9) -> 2009 | D9: 817 Oak St | E9: Bridgeport | F9: Apartment | G9: 3 | H9: 2765 | I9: 479403 | J9: =Raw_Data!$I9/Raw_Data!$H9 -> 173.38264
A10: 40929 | B10: =TEXT(Raw_Data!$A10, "MMM") -> Jan | C10: =YEAR(Raw_Data!$A10) -> 2012 | D10: 101 Oak St | E10: Stamford | F10: Townhouse | G10: 5 | H10: 2051 | I10: 291284 | J10: =Raw_Data!$I10/Raw_Data!$H10 -> 142.02048
A11: 40416 | B11: =TEXT(Raw_Data!$A11, "MMM") -> Aug | C11: =YEAR(Raw_Data!$A11) -> 2010 | D11: 674 Elm St | E11: Danbury | F11: Condo | H11: 1354 | I11: 835777 | J11: =Raw_Data!$I11/Raw_Data!$H11 -> 617.26514
A12: 41530 | B12: =TEXT(Raw_Data!$A12, "MMM") -> Sep | C12: =YEAR(Raw_Data!$A12) -> 2013 | D12: 580 Main St | E12: Waterbury | F12: Townhouse | G12: 2 | H12: 1033 | I12: 687709 | J12: =Raw_Data!$I12/Raw_Data!$H12 -> 665.73959
A13: 38705 | B13: =TEXT(Raw_Data!$A13, "MMM") -> Dec | C13: =YEAR(Raw_Data!$A13) -> 2005 | D13: 158 Maple Ave | E13: Hartford | F13: Condo | H13: 3210 | I13: 771659 | J13: =Raw_Data!$I13/Raw_Data!$H13 -> 240.39221
A14: 42375 | B14: =TEXT(Raw_Data!$A14, "MMM") -> Jan | C14: =YEAR(Raw_Data!$A14) -> 2016 | D14: 794 Pine Rd | E14: Bridgeport | F14: Apartment | G14: 5 | H14: 3160 | I14: 835846 | J14: =Raw_Data!$I14/Raw_Data!$H14 -> 264.50823
A15: 41055 | B15: =TEXT(Raw_Data!$A15, "MMM") -> May | C15: =YEAR(Raw_Data!$A15) -> 2012 | D15: 287 Oak St | E15: Hartford | F15: Townhouse | H15: 1423 | I15: 131127 | J15: =Raw_Data!$I15/Raw_Data!$H15 -> 92.148278
A16: 41520 | B16: =TEXT(Raw_Data!$A16, "MMM") -> Sep | C16: =YEAR(Raw_Data!$A16) -> 2013 | D16: 523 Oak St | E16: Danbury | F16: Townhouse | G16: 5 | H16: 1958 | I16: 892241 | J16: =Raw_Data!$I16/Raw_Data!$H16 -> 455.68999
A17: 39396 | B17: =TEXT(Raw_Data!$A17, "MMM") -> Nov | C17: =YEAR(Raw_Data!$A17) -> 2007 | D17: 121 Oak St | E17: Bridgeport | F17: Apartment | G17: 4 | H17: 3240 | I17: 119911 | J17: =Raw_Data!$I17/Raw_Data!$H17 -> 37.009568
A18: 42810 | B18: =TEXT(Raw_Data!$A18, "MMM") -> Mar | C18: =YEAR(Raw_Data!$A18) -> 2017 | D18: 774 Main St | E18: Danbury | F18: Townhouse | G18: 4 | H18: 1356 | I18: 813626 | J18: =Raw_Data!$I18/Raw_Data!$H18 -> 600.01917
A19: 39305 | B19: =TEXT(Raw_Data!$A19, "MMM") -> Aug | C19: =YEAR(Raw_Data!$A19) -> 2007 | D19: 479 Pine Rd | E19: Waterbury | F19: Single Family | H19: 2101 | I19: 180289 | J19: =Raw_Data!$I19/Raw_Data!$H19 -> 85.811042
A20: 38221 | B20: =TEXT(Raw_Data!$A20, "MMM") -> Aug | C20: =YEAR(Raw_Data!$A20) -> 2004 | D20: 473 Oak St | E20: Bridgeport | F20: Apartment | G20: 3 | H20: 1602 | I20: 239725 | J20: =Raw_Data!$I20/Raw_Data!$H20 -> 149.64107
A21: 42103 | B21: =TEXT(Raw_Data!$A21, "MMM") -> Apr | C21: =YEAR(Raw_Data!$A21) -> 2015 | D21: 871 Pine Rd | E21: Hartford | F21: Apartment | H21: 2286 | I21: 462030 | J21: =Raw_Data!$I21/Raw_Data!$H21 -> 202.11286
A22: 38467 | B22: =TEXT(Raw_Data!$A22, "MMM") -> Apr | C22: =YEAR(Raw_Data!$A22) -> 2005 | D22: 994 Main St | E22: Bridgeport | F22: Apartment | H22: 1822 | I22: 286247 | J22: =Raw_Data!$I22/Raw_Data!$H22 -> 157.10593
A23: 38090 | B23: =TEXT(Raw_Data!$A23, "MMM") -> Apr | C23: =YEAR(Raw_Data!$A23) -> 2004 | D23: 512 Elm St | E23: Norwalk | F23: Townhouse | G23: 3 | H23: 1269 | I23: 597788 | J23: =Raw_Data!$I23/Raw_Data!$H23 -> 471.07013
A24: 39387 | B24: =TEXT(Raw_Data!$A24, "MMM") -> Nov | C24: =YEAR(Raw_Data!$A24) -> 2007 | D24: 273 Main St | E24: New Haven | F24: Condo | G24: 3 | H24: 1012 | I24: 313143 | J24: =Raw_Data!$I24/Raw_Data!$H24 -> 309.42984
A25: 37104 | B25: =TEXT(Raw_Data!$A25, "MMM") -> Aug | C25: =YEAR(Raw_Data!$A25) -> 2001 | D25: 429 Oak St | E25: New Haven | F25: Condo | G25: 2 | H25: 3391 | I25: 378029 | J25: =Raw_Data!$I25/Raw_Data!$H25 -> 111.48009
A26: 40576 | B26: =TEXT(Raw_Data!$A26, "MMM") -> Feb | C26: =YEAR(Raw_Data!$A26) -> 2011 | D26: 970 Pine Rd | E26: Danbury | F26: Single Family | G26: 2 | H26: 2229 | I26: 513043 | J26: =Raw_Data!$I26/Raw_Data!$H26 -> 230.16734
A27: 38636 | B27: =TEXT(Raw_Data!$A27, "MMM") -> Oct | C27: =YEAR(Raw_Data!$A27) -> 2005 | D27: 719 Elm St | E27: Norwalk | F27: Single Family | G27: 3 | H27: 1485 | I27: 737040 | J27: =Raw_Data!$I27/Raw_Data!$H27 -> 496.32323
A28: 43362 | B28: =TEXT(Raw_Data!$A28, "MMM") -> Sep | C28: =YEAR(Raw_Data!$A28) -> 2018 | D28: 805 Main St | E28: Bridgeport | F28: Apartment | G28: 3 | H28: 1628 | I28: 762843 | J28: =Raw_Data!$I28/Raw_Data!$H28 -> 468.57678
A29: 40681 | B29: =TEXT(Raw_Data!$A29, "MMM") -> May | C29: =YEAR(Raw_Data!$A29) -> 2011 | D29: 847 Elm St | E29: New Haven | F29: Condo | H29: 1225 | I29: 268402 | J29: =Raw_Data!$I29/Raw_Data!$H29 -> 219.10367
A30: 43557 | B30: =TEXT(Raw_Data!$A30, "MMM") -> Apr | C30: =YEAR(Raw_Data!$A30) -> 2019 | D30: 820 Pine Rd | E30: Norwalk | F30: Apartment | H30: 1940 | I30: 601174 | J30: =Raw_Data!$I30/Raw_Data!$H30 -> 309.88351
A31: 43404 | B31: =TEXT(Raw_Data!$A31, "MMM") -> Oct | C31: =YEAR(Raw_Data!$A31) -> 2018 | D31: 211 Maple Ave | E31: Hartford | F31: Condo | G31: 4 | H31: 2647 | I31: 561582 | J31: =Raw_Data!$I31/Raw_Data!$H31 -> 212.15791
A32: 41412 | B32: =TEXT(Raw_Data!$A32, "MMM") -> May | C32: =YEAR(Raw_Data!$A32) -> 2013 | D32: 337 Elm St | E32: New Haven | F32: Townhouse | G32: 2 | H32: 2622 | I32: 727671 | J32: =Raw_Data!$I32/Raw_Data!$H32 -> 277.52517
A33: 41612 | B33: =TEXT(Raw_Data!$A33, "MMM") -> Dec | C33: =YEAR(Raw_Data!$A33) -> 2013 | D33: 796 Pine Rd | E33: New Haven | F33: Apartment | G33: 4 | H33: 3151 | I33: 757685 | J33: =Raw_Data!$I33/Raw_Data!$H33 -> 240.45858
A34: 40413 | B34: =TEXT(Raw_Data!$A34, "MMM") -> Aug | C34: =YEAR(Raw_Data!$A34) -> 2010 | D34: 819 Main St | E34: Norwalk | F34: Townhouse | H34: 2141 | I34: 897938 | J34: =Raw_Data!$I34/Raw_Data!$H34 -> 419.40121
A35: 39571 | B35: =TEXT(Raw_Data!$A35, "MMM") -> May | C35: =YEAR(Raw_Data!$A35) -> 2008 | D35: 581 Oak St | E35: Stamford | F35: Apartment | H35: 1044 | I35: 297981 | J35: =Raw_Data!$I35/Raw_Data!$H35 -> 285.42241
A36: 42087 | B36: =TEXT(Raw_Data!$A36, "MMM") -> Mar | C36: =YEAR(Raw_Data!$A36) -> 2015 | D36: 744 Maple Ave | E36: Hartford | F36: Apartment | G36: 2 | H36: 1525 | I36: 227723 | J36: =Raw_Data!$I36/Raw_Data!$H36 -> 149.32656
A37: 37024 | B37: =TEXT(Raw_Data!$A37, "MMM") -> May | C37: =YEAR(Raw_Data!$A37) -> 2001 | D37: 953 Pine Rd | E37: Hartford | F37: Condo | G37: 2 | H37: 945 | I37: 545376 | J37: =Raw_Data!$I37/Raw_Data!$H37 -> 577.11746
A38: 41157 | B38: =TEXT(Raw_Data!$A38, "MMM") -> Sep | C38: =YEAR(Raw_Data!$A38) -> 2012 | D38: 698 Pine Rd | E38: Bridgeport | F38: Condo | G38: 5 | H38: 2768 | I38: 224301 | J38: =Raw_Data!$I38/Raw_Data!$H38 -> 81.033598
A39: 37810 | B39: =TEXT(Raw_Data!$A39, "MMM") -> Jul | C39: =YEAR(Raw_Data!$A39) -> 2003 | D39: 689 Pine Rd | E39: Bridgeport | F39: Townhouse | G39: 3 | H39: 2863 | I39: 626032 | J39: =Raw_Data!$I39/Raw_Data!$H39 -> 218.66294
A40: 37603 | B40: =TEXT(Raw_Data!$A40, "MMM") -> Dec | C40: =YEAR(Raw_Data!$A40) -> 2002 | D40: 844 Elm St | E40: Waterbury | F40: Townhouse | G40: 5 | H40: 819 | I40: 517460 | J40: =Raw_Data!$I40/Raw_Data!$H40 -> 631.81929
...

Sheet AveragePriceByYear
A3: Row Labels | B3: Average of Sale_Price
A4: 2001 | B4: 497700.1
A5: 2002 | B5: 495067.01
A6: 2003 | B6: 502913.32
A7: 2004 | B7: 509024.57
A8: 2005 | B8: 501520.87
A9: 2006 | B9: 512843.98
A10: 2007 | B10: 494836.43
A11: 2008 | B11: 506165.3
A12: 2009 | B12: 489313.43
A13: 2010 | B13: 516065.83
A14: 2011 | B14: 506498.73
A15: 2012 | B15: 473714.02
... A23: 2020 | B23: 500313.45
A24: Grand Total | B24: 500619.27

Sheet NumberOfPropertySalesByYear
A3: Row Labels | B3: Count of Sale_Price
A4: 2004 | B4: 274
A5: 2009 | B5: 262
A6: 2005 | B6: 261
A7: 2006 | B7: 259
A8: 2018 | B8: 259
A9: 2013 | B9: 254
A10: 2011 | B10: 254
A11: 2019 | B11: 251
A12: 2016 | B12: 246
A13: 2020 | B13: 243
A14: 2001 | B14: 242
A15: 2007 | B15: 240
... A23: 2015 | B23: 223
A24: Grand Total | B24: 4901

Sheet NumberOfPropertySalesByTown
A3: Row Labels | B3: Count of Sale_Price
A4: Norwalk | B4: 464
A5: Waterbury | B5: 487
A6: Danbury | B6: 497
A7: Stamford | B7: 516
A8: Bridgeport | B8: 952
A9: Hartford | B9: 987 | J9: Ave
A10: New Haven | B10: 998
A11: Grand Total | B11: 4901

Sheet AveragePropertyPriceByTown
A3: Row Labels | B3: Average of Sale_Price
A4: New Haven | B4: 490024.89
A5: Bridgeport | B5: 493043.44
A6: Hartford | B6: 501577.18
A7: Waterbury | B7: 503075.79
A8: Danbury | B8: 505984.57
A9: Stamford | B9: 508894.35 | J9: Ave
A10: Norwalk | B10: 519384.57
A11: Grand Total | B11: 500619.27

Sheet AveragePropertyPricePerSqFt
A3: Row Labels | B3: Average of Price Per Sq Ft
A4: New Haven | B4: 259.04309
A5: Danbury | B5: 259.09382
A6: Bridgeport | B6: 260.5532
A7: Waterbury | B7: 266.13523
A8: Hartford | B8: 269.80365
A9: Norwalk | B9: 275.75741
A10: Stamford | B10: 276.9192
A11: Grand Total | B11: 265.67952

Sheet PropertySalesDistribution
A3: Row Labels | B3: Count of Sale_Price
A4: Single Family | B4: 1209
A5: Condo | B5: 1215
A6: Apartment | B6: 1221
A7: Townhouse | B7: 1256
A8: Grand Total | B8: 4901

Sheet PriceForcastModel
A1: Row Labels | B1: Average of Sale_Price | C1: Forecast(Average of Sale_Price) | D1: Lower Confidence Bound(Average of Sale_Price) | E1: Upper Confidence Bound(Average of Sale_Price)
A2: 2001 | B2: 497700.1
A3: 2002 | B3: 495067.01
A4: 2003 | B4: 502913.32
A5: 2004 | B5: 509024.57
A6: 2005 | B6: 501520.87
A7: 2006 | B7: 512843.98
A8: 2007 | B8: 494836.43
A9: 2008 | B9: 506165.3
A10: 2009 | B10: 489313.43
A11: 2010 | B11: 516065.83
A12: 2011 | B12: 506498.73
A13: 2012 | B13: 473714.02
... A20: 2019 | B20: 478898.9
A21: 2020 | B21: 500313.45 | C21: 500313.45 | D21: 500313.45 | E21: 500313.45
A22: 2021 | C22: =_xlfn.FORECAST.ETS(A22,$B$2:$B$21,$A$2:$A$21,1,1) -> 497142.6 | D22: =C22-_xlfn.FORECAST.ETS.CONFINT(A22,$B$2:$B$21,$A$2:$A$21,0.95,1,1) -> 473258.92 | E22: =C22+_xlfn.FORECAST.ETS.CONFINT(A22,$B$2:$B$21,$A$2:$A$21,0.95,1,1) -> 521026.28
A23: 2022 | C23: =_xlfn.FORECAST.ETS(A23,$B$2:$B$21,$A$2:$A$21,1,1) -> 497137.81 | D23: =C23-_xlfn.FORECAST.ETS.CONFINT(A23,$B$2:$B$21,$A$2:$A$21,0.95,1,1) -> 473254.02 | E23: =C23+_xlfn.FORECAST.ETS.CONFINT(A23,$B$2:$B$21,$A$2:$A$21,0.95,1,1) -> 521021.59
A24: 2023 | C24: =_xlfn.FORECAST.ETS(A24,$B$2:$B$21,$A$2:$A$21,1,1) -> 497133.01 | D24: =C24-_xlfn.FORECAST.ETS.CONFINT(A24,$B$2:$B$21,$A$2:$A$21,0.95,1,1) -> 473249.04 | E24: =C24+_xlfn.FORECAST.ETS.CONFINT(A24,$B$2:$B$21,$A$2:$A$21,0.95,1,1) -> 521016.99
A25: 2024 | C25: =_xlfn.FORECAST.ETS(A25,$B$2:$B$21,$A$2:$A$21,1,1) -> 497128.22 | D25: =C25-_xlfn.FORECAST.ETS.CONFINT(A25,$B$2:$B$21,$A$2:$A$21,0.95,1,1) -> 473243.95 | E25: =C25+_xlfn.FORECAST.ETS.CONFINT(A25,$B$2:$B$21,$A$2:$A$21,0.95,1,1) -> 521012.5
A26: 2025 | C26: =_xlfn.FORECAST.ETS(A26,$B$2:$B$21,$A$2:$A$21,1,1) -> 497123.43 | D26: =C26-_xlfn.FORECAST.ETS.CONFINT(A26,$B$2:$B$21,$A$2:$A$21,0.95,1,1) -> 473238.73 | E26: =C26+_xlfn.FORECAST.ETS.CONFINT(A26,$B$2:$B$21,$A$2:$A$21,0.95,1,1) -> 521008.14
A27: 2026 | C27: =_xlfn.FORECAST.ETS(A27,$B$2:$B$21,$A$2:$A$21,1,1) -> 497118.64 | D27: =C27-_xlfn.FORECAST.ETS.CONFINT(A27,$B$2:$B$21,$A$2:$A$21,0.95,1,1) -> 473233.35 | E27: =C27+_xlfn.FORECAST.ETS.CONFINT(A27,$B$2:$B$21,$A$2:$A$21,0.95,1,1) -> 521003.93
